<?xml version="1.0" ?>
<robot xmlns:xacro="http://www.ros.org/wiki/xacro" name="iroc_rover">
<xacro:property name="update_rate" default="30"/>
  <joint name="joint_1_2" type="fixed">
    <parent link="arm_base_shoulder_1"/>
    <child link="shoulder_elbow_2"/>
    <origin xyz="0      0.15    0.19999" rpy="1.57 0   0"/>
    <axis xyz="0 0 0"/>
    <limit lower="0" upper="0" effort="0" velocity="0"/>
  </joint>
    <joint name="joint_2_3" type="prismatic">
    <parent link="shoulder_elbow_2"/>
    <child link="elbow_palm_3"/>
    <origin xyz="0   -0.1  -0.15" rpy="-1.57  0    0"/>
    <axis xyz="0  0 -1"/>
    <limit lower="-1.79769e+308" upper="1.79769e+308" effort="10" velocity="10"/>
    <dynamics damping="0.7"/>
  </joint>
  <joint name="joint_3_4" type="revolute">
    <parent link="elbow_palm_3"/>
    <child link="palm_finger_4"/>
    <origin xyz="0       0      -0.10999" rpy="3.14159 1.51159 3.14159"/>
    <axis xyz="1 0 0"/>
    <limit lower="-1.79769e+308" upper="1.79769e+308" effort="10" velocity="10"/>
    <!-- <dynamics damping="0.7"/> -->
  </joint>
  <joint name="base_back_left_wheel" type="revolute">
    <parent link="base_link"/>
    <child link="back_left"/>
    <origin xyz="-1.32033 -0.47514  0.697" rpy="-1.5708   0       1.61257"/>
    <axis xyz="0  0 -1"/>
    <limit lower="-1.79769e+308" upper="1.79769e+308" effort="10" velocity="10"/>
  </joint>
  <joint name="base_front_left_wheel" type="revolute">
    <parent link="base_link"/>
    <child link="front_left"/>
    <origin xyz="-1.35374  0.32415  0.697" rpy="-1.5708   0       1.61257"/>
    <axis xyz="0  0 -1"/>
    <limit lower="-1.79769e+308" upper="1.79769e+308" effort="10" velocity="10"/>
  </joint>
  <joint name="base_front_right_wheel" type="revolute">
    <parent link="base_link"/>
    <child link="front_right"/>
    <origin xyz="-0.2547   0.37009  0.697" rpy="-1.5708   0       1.61257"/>
    <axis xyz="0  0 -1"/>
    <limit lower="-1.79769e+308" upper="1.79769e+308" effort="10" velocity="10"/>
  </joint>
  <joint name="base_back_right_wheel" type="revolute">
    <parent link="base_link"/>
    <child link="back_right"/>
    <origin xyz="-0.22129 -0.4292   0.697" rpy="-1.5708   0       1.61257"/>
    <axis xyz="0  0 -1"/>
    <limit lower="-1.79769e+308" upper="1.79769e+308" effort="10" velocity="10"/>
  </joint>
  <joint name="joint_0_1" type="revolute">
    <parent link="base_link"/>
    <child link="arm_base_shoulder_1"/>
    <origin xyz="-0.90189 0.6 1.98" rpy="0      0      0"/>
    <axis xyz="0 0 1"/>
    <limit lower="-1.79769e+308" upper="1.79769e+308" effort="10.0" velocity="1.0"/>
    <!-- <dynamics damping="0.7"/> -->
  </joint>

   <transmission name="tran_0_1">
    <type>transmission_interface/SimpleTransmission</type>
    <joint name="joint_0_1">
      <hardwareInterface>hardware_interface/EffortJointInterface</hardwareInterface>
    </joint>
    <actuator name="motor_0_1">
      <hardwareInterface>hardware_interface/EffortJointInterface</hardwareInterface>
      <mechanicalReduction>1</mechanicalReduction>
    </actuator>
  </transmission>

   <transmission name="tran_2_3">
    <type>transmission_interface/SimpleTransmission</type>
    <joint name="joint_2_3">
      <hardwareInterface>hardware_interface/EffortJointInterface</hardwareInterface>
    </joint>
    <actuator name="motor_2_3">
      <hardwareInterface>hardware_interface/EffortJointInterface</hardwareInterface>
      <mechanicalReduction>1</mechanicalReduction>
    </actuator>
  </transmission>

   <transmission name="tran_3_4">
    <type>transmission_interface/SimpleTransmission</type>
    <joint name="joint_3_4">
      <hardwareInterface>hardware_interface/EffortJointInterface</hardwareInterface>
    </joint>
    <actuator name="motor_3_4">
      <hardwareInterface>hardware_interface/EffortJointInterface</hardwareInterface>
      <mechanicalReduction>1</mechanicalReduction>
    </actuator>
  </transmission>

  <link name="base_link">
    <inertial>
      <mass value="1"/>
      <origin xyz="0 0 0" rpy="0 0 0"/>
      <inertia ixx="0.166667" ixy="0" ixz="0" iyy="0.166667" iyz="0" izz="0.166667"/>
    </inertial>
    <collision name="robot_with_arm_final__collision">
      <origin xyz="-0.79586  0.14729  1.0849" rpy="0      0      1.61257"/>
      <geometry>
        <box size="1 1 0.4"/>
      </geometry>
    </collision>
    <visual name="robot_with_arm_final__visual">
      <origin xyz="-0.79586  0.14729  1.0849" rpy="0      0      1.61257"/>
      <geometry>
        <box size="1 1 0.4"/>
      </geometry>
    </visual>
  </link>
  <link name="back_left">
    <inertial>
      <mass value="1"/>
      <origin xyz="0 0 0" rpy="0 0 0"/>
      <inertia ixx="0.145833" ixy="0" ixz="0" iyy="0.145833" iyz="0" izz="0.125"/>
    </inertial>
    <collision name="robot_with_arm_final__collision">
      <origin xyz="0 0 0" rpy="0 0 0"/>
      <geometry>
        <cylinder radius="0.3" length="0.1"/>
      </geometry>
    </collision>
    <visual name="robot_with_arm_final__visual">
      <origin xyz="0 0 0" rpy="0 0 0"/>
      <geometry>
        <cylinder radius="0.3" length="0.1"/>
      </geometry>
    </visual>
  </link>
  <link name="front_right">
    <inertial>
      <mass value="1"/>
      <origin xyz="0 0 0" rpy="0 0 0"/>
      <inertia ixx="0.145833" ixy="0" ixz="0" iyy="0.145833" iyz="0" izz="0.125"/>
    </inertial>
    <collision name="robot_with_arm_final__collision">
      <origin xyz="0 0 0" rpy="0 0 0"/>
      <geometry>
        <cylinder radius="0.3" length="0.1"/>
      </geometry>
    </collision>
    <visual name="robot_with_arm_final__visual">
      <origin xyz="0 0 0" rpy="0 0 0"/>
      <geometry>
        <cylinder radius="0.3" length="0.1"/>
      </geometry>
    </visual>
  </link>
  <link name="front_left">
    <inertial>
      <mass value="1"/>
      <origin xyz="0 0 0" rpy="0 0 0"/>
      <inertia ixx="0.145833" ixy="0" ixz="0" iyy="0.145833" iyz="0" izz="0.125"/>
    </inertial>
    <collision name="robot_with_arm_final__collision">
      <origin xyz="0 0 0" rpy="0 0 0"/>
      <geometry>
        <cylinder radius="0.3" length="0.1"/>
      </geometry>
    </collision>
    <visual name="robot_with_arm_final__visual">
      <origin xyz="0 0 0" rpy="0 0 0"/>
      <geometry>
        <cylinder radius="0.3" length="0.1"/>
      </geometry>
    </visual>
  </link>
  <link name="back_right">
    <inertial>
      <mass value="1"/>
      <origin xyz="0 0 0" rpy="0 0 0"/>
      <inertia ixx="0.145833" ixy="0" ixz="0" iyy="0.145833" iyz="0" izz="0.125"/>
    </inertial>
    <collision name="robot_with_arm_final__collision">
      <origin xyz="0 0 0" rpy="0 0 0"/>
      <geometry>
        <cylinder radius="0.3" length="0.1"/>
      </geometry>
    </collision>
    <visual name="robot_with_arm_final__visual">
      <origin xyz="0 0 0" rpy="0 0 0"/>
      <geometry>
        <cylinder radius="0.3" length="0.1"/>
      </geometry>
    </visual>
  </link>
  <link name="arm_base_shoulder_1">
    <inertial>
      <mass value="0.001"/>
      <origin xyz="0 0 0" rpy="0 0 0"/>
      <inertia ixx="1.336e-05" ixy="0" ixz="0" iyy="1.336e-05" iyz="0" izz="5e-08"/>
    </inertial>
    <collision name="robot_with_arm_final__collision">
      <origin xyz="0 0 0" rpy="0 0 0"/>
      <geometry>
        <cylinder radius="0.01" length="0.4"/>
      </geometry>
    </collision>
    <visual name="robot_with_arm_final__visual">
      <origin xyz="0 0 0" rpy="0 0 0"/>
      <geometry>
        <cylinder radius="0.01" length="0.4"/>
      </geometry>
    </visual>
  </link>
  <link name="elbow_palm_3">
    <inertial>
      <mass value="0.001"/>
      <origin xyz="0 0 0" rpy="0 0 0"/>
      <inertia ixx="3.36e-06" ixy="0" ixz="0" iyy="3.36e-06" iyz="0" izz="5e-08"/>
    </inertial>
    <collision name="robot_with_arm_final__collision">
      <origin xyz="0 0 0" rpy="0 0 0"/>
      <geometry>
        <cylinder radius="0.01" length="0.2"/>
      </geometry>
    </collision>
    <visual name="robot_with_arm_final__visual">
      <origin xyz="0 0 0" rpy="0 0 0"/>
      <geometry>
        <cylinder radius="0.01" length="0.2"/>
      </geometry>
    </visual>
  </link>
  <link name="palm_finger_4">
    <inertial>
      <mass value="0.001"/>
      <origin xyz="0 0 0" rpy="0 0 0"/>
      <inertia ixx="8.6e-07" ixy="0" ixz="0" iyy="8.6e-07" iyz="0" izz="5e-08"/>
    </inertial>
    <collision name="robot_with_arm_final__collision">
      <origin xyz="0 0 0" rpy="0   -0.06  0"/>
      <geometry>
        <cylinder radius="0.01" length="0.1"/>
      </geometry>
    </collision>
    <visual name="robot_with_arm_final__visual">
      <origin xyz="0 0 0" rpy="0   -0.06  0"/>
      <geometry>
        <cylinder radius="0.01" length="0.1"/>
      </geometry>
    </visual>
  </link>
  <link name="shoulder_elbow_2">
    <inertial>
      <mass value="0.001"/>
      <origin xyz="0 0 0" rpy="0 0 0"/>
      <inertia ixx="7.52e-06" ixy="0" ixz="0" iyy="7.52e-06" iyz="0" izz="5e-08"/>
    </inertial>
    <collision name="robot_with_arm_final__collision">
      <origin xyz="0 0 0" rpy="0 0 0"/>
      <geometry>
        <cylinder radius="0.01" length="0.3"/>
      </geometry>
    </collision>
    <visual name="robot_with_arm_final__visual">
      <origin xyz="0 0 0" rpy="0 0 0"/>
      <geometry>
        <cylinder radius="0.01" length="0.3"/>
      </geometry>
    </visual>
  </link>
  <!-- camera link -->
    <link name="camera_link">
    <inertial>
      <mass value="1"/>
      <origin xyz="0 0 10" rpy="0 0 0"/>
      <inertia ixx="0.166667" ixy="0" ixz="0" iyy="0.166667" iyz="0" izz="0.166667"/>
    </inertial>
    <collision name="robot_with_arm_final__collision">
      <origin xyz="-0.79586  0.14729  1.0849" rpy="0      0      1.61257"/>
      <geometry>
        <box size="0.4 0.4 0.4"/>
      </geometry>
    </collision>
    <visual name="robot_with_arm_final__visual">
      <origin xyz="-0.79586  0.14729  1.0849" rpy="0      0      1.61257"/>
      <geometry>
        <box size="0.4 0.4 0.4"/>
      </geometry>
    </visual>
  </link>
  
  <!-- plugin -->
  <gazebo>
  <plugin name="gazebo_ros_control" filename="libgazebo_ros_control.so">
    <robotNamespace>/iroc_rover</robotNamespace>
  </plugin>
</gazebo>
   <gazebo>
    <plugin name="skid_steer_drive_controller" filename="libgazebo_ros_skid_steer_drive.so">
      <updateRate>10.0</updateRate>
      <robotNamespace>/</robotNamespace>
      <leftFrontJoint>base_front_left_wheel</leftFrontJoint>
      <rightFrontJoint>base_front_right_wheel</rightFrontJoint>
      <leftRearJoint>base_back_left_wheel</leftRearJoint>
      <rightRearJoint>base_back_right_wheel</rightRearJoint>
      <wheelSeparation>1</wheelSeparation>
      <wheelDiameter>0.2</wheelDiameter>
      <robotBaseFrame>base_link</robotBaseFrame>
      <torque>20</torque><!-- _filtered -->
      <commandTopic>cmd_vel</commandTopic>
      <odometryTopic>odom</odometryTopic>
      <odometryFrame>odom</odometryFrame>
      <broadcastTF>true</broadcastTF>
    </plugin>
  </gazebo>

  <gazebo reference="imu_link">
    <gravity>true</gravity>
    <sensor name="imu_sensor" type="imu">
      <always_on>true</always_on>
      <update_rate>100</update_rate>
      <visualize>true</visualize>
      <topic>__default_topic__</topic>
      <plugin filename="libgazebo_ros_imu_sensor.so" name="imu_plugin">
        <topicName>imu</topicName>
        <bodyName>imu_link</bodyName>
        <updateRateHZ>10.0</updateRateHZ>
        <gaussianNoise>0.0</gaussianNoise>
        <xyzOffset>0 0 0</xyzOffset>
        <rpyOffset>0 0 0</rpyOffset>
        <frameName>imu_link</frameName>
        <initialOrientationAsReference>false</initialOrientationAsReference>
      </plugin>
      <pose>0 0 0 0 0 0</pose>
    </sensor>
  </gazebo>

<gazebo reference="camera_link">
    <!-- <sensor type="camera" name="camera1"> -->
    <sensor type="depth" name="camera1">
      <update_rate>15.0</update_rate>
      <camera name="head">
        <horizontal_fov>1.3962634</horizontal_fov>
        <image>
          <width>800</width>
          <height>800</height>
          <format>B8G8R8</format>
        </image>
        <clip>
          <near>0.02</near>
          <far>300</far>
        </clip>
        <noise>
          <type>gaussian</type>
          <!-- Noise is sampled independently per pixel on each frame.
               That pixel's noise value is added to each of its color
               channels, which at that point lie in the range [0,1]. -->
          <mean>0.0</mean>
          <stddev>0.007</stddev>
        </noise>
      </camera>
    
      <!-- <plugin name="camera_controller" filename="libgazebo_ros_camera.so"> -->
      <!--   <alwaysOn>true</alwaysOn> -->
      <!--   <updateRate>0.0</updateRate> -->
      <!--   <cameraName>camera</cameraName> -->
      <!--   <imageTopicName>image_raw</imageTopicName> -->
      <!--   <cameraInfoTopicName>camera_info</cameraInfoTopicName> -->
      <!--   <frameName>camera_link</frameName> -->
      <!--   <hackBaseline>0.07</hackBaseline> -->
      <!--   <distortionK1>0.0</distortionK1> -->
      <!--   <distortionK2>0.0</distortionK2> -->
      <!--   <distortionK3>0.0</distortionK3> -->
      <!--   <distortionT1>0.0</distortionT1> -->
      <!--   <distortionT2>0.0</distortionT2> -->
    <!-- </plugin> --> 
      <plugin name="camera_plugin" filename="libgazebo_ros_openni_kinect.so">
        <baseline>0.2</baseline>
        <alwaysOn>true</alwaysOn>
        <!-- Keep this zero, update_rate in the parent <sensor> tag
          will control the frame rate. -->
        <updateRate>0.0</updateRate>
        <cameraName>mrt/camera</cameraName>
        <imageTopicName>color/image_raw</imageTopicName>
        <cameraInfoTopicName>color/camera_info</cameraInfoTopicName>
        <depthImageTopicName>depth/image_rect_raw</depthImageTopicName>
        <depthImageCameraInfoTopicName>depth/camera_info</depthImageCameraInfoTopicName>
        <pointCloudTopicName>depth/color/points</pointCloudTopicName>
        <frameName>camera_link_optical</frameName>
        <pointCloudCutoff>0.5</pointCloudCutoff>
        <pointCloudCutoffMax>7.0</pointCloudCutoffMax>
        <distortionK1>0</distortionK1>
        <distortionK2>0</distortionK2>
        <distortionK3>0</distortionK3>
        <distortionT1>0</distortionT1>
        <distortionT2>0</distortionT2>
        <CxPrime>0</CxPrime>
        <Cx>0</Cx>
        <Cy>0</Cy>
        <focalLength>0</focalLength>
      </plugin>
    </sensor>
  </gazebo>

</robot>
